# 分类
## error
自定义异常。
```sol
error TransferNotOwner(); // 自定义error
revert TransferNotOwner(); // 抛出自定义异常
```

- 省[Gas](Gas.md)
- 搭配`revert`使用
## require
```sol
require(bool,(string|error)?)
```
检查一个条件,为false则抛出异常；

- ⚠️退还剩余的 [Gas](Gas.md)（在 EVM中是通过中断交易的执行来退还未消耗的 Gas）。
- `gas`随着描述异常的字符串长度增加，比`error`命令要高。
## revert
```sol
revert((string|error)?)
```
手动调用，回滚交易并return 错误信息

  💡传入自定义Error实例会更省gas；

- ⚠️退还剩余的 [Gas](Gas.md)
- 返回值类型为[`bytes`](变量类型.md#`bytes`)

## assert
```sol
assert(bool)
```
用于内部错误捕获，通常用来验证代码的不可达状态，可以在合约内检查不变性条件；不可自定义抛出的错误。

- ⚠️Solidity 0.8.0之前的版本，`assert`抛出的是一个 `panic exception`，会把剩余的 `gas` 全部消耗，不会返还。

## try...catch
```sol
try here_is_some_logic{
// 成功分支
}catch{
// 错误分支
}
```
- try可单独使用
- 能被用于`external`函数或`public`函数
- 能被用于创建合约时`constructor`（被视为`external`函数）的调用。
- try代码块内的revert会被catch本身捕获

如果调用的函数有返回值，那么必须在`try`之后声明`returns(returnType val)`，并且在`try`模块中可以使用返回的变量；如果是创建合约，那么返回值是新创建的合约变量。
```sol
try externalContract.f() returns(returnType val){ // call成功的情况下 运行一些代码 } catch { // call失败的情况下 运行一些代码 }
```

另外，`catch`模块支持捕获特殊的异常原因：
```sol
try externalContract.f() returns(returnType){ 
	// call成功的情况下 运行一些代码
} catch Error(string memory /*reason*/) { 
	// 捕获revert("reasonString") 和 require(false, "reasonString") 
} catch Panic(uint /*errorCode*/) { 
	// 捕获Panic导致的错误 例如assert失败 溢出 除零 数组访问越界 
} catch (bytes memory /*lowLevelData*/) { 
	// 如果发生了revert且上面2个异常类型匹配都失败了 会进入该分支 
	// 例如revert() require(false) revert自定义类型的error 
}
```